<sdf version='1.10'>
  <world name='Moving_robot'>
    <physics name='1ms' type='ignored'>
      <max_step_size>0.001</max_step_size>
      <real_time_factor>1</real_time_factor>
      <real_time_update_rate>1000</real_time_update_rate>
    </physics>
    <plugin name='gz::sim::systems::Physics' filename='gz-sim-physics-system'/>
    <plugin name='gz::sim::systems::UserCommands' filename='gz-sim-user-commands-system'/>
    <plugin name='gz::sim::systems::SceneBroadcaster' filename='gz-sim-scene-broadcaster-system'/>
    <plugin name='gz::sim::systems::Imu' filename='gz-sim-imu-system'/>
    <plugin name='gz::sim::systems::Sensors' filename='gz-sim-sensors-system'>
      <render_engine>ogre2</render_engine>
    </plugin>
    <plugin name='gz::sim::systems::TriggeredPublisher' filename='gz-sim-triggered-publisher-system'>
      <input type='gz.msgs.Int32' topic='/keyboard/keypress'>
        <match field='data'>16777234</match>
      </input>
      <output type='gz.msgs.Twist' topic='/cmd_vel'>linear: {x: 0.0}, angular: {z: 0.5}</output>
    </plugin>
    <plugin name='gz::sim::systems::TriggeredPublisher' filename='gz-sim-triggered-publisher-system'>
      <input type='gz.msgs.Int32' topic='/keyboard/keypress'>
        <match field='data'>16777235</match>
      </input>
      <output type='gz.msgs.Twist' topic='/cmd_vel'>linear: {x: 0.5}, angular: {z: 0.0}</output>
    </plugin>
    <plugin name='gz::sim::systems::TriggeredPublisher' filename='gz-sim-triggered-publisher-system'>
      <input type='gz.msgs.Int32' topic='/keyboard/keypress'>
        <match field='data'>16777236</match>
      </input>
      <output type='gz.msgs.Twist' topic='/cmd_vel'>linear: {x: 0.0}, angular: {z: -0.5}</output>
    </plugin>
    <plugin name='gz::sim::systems::TriggeredPublisher' filename='gz-sim-triggered-publisher-system'>
      <input type='gz.msgs.Int32' topic='/keyboard/keypress'>
        <match field='data'>16777237</match>
      </input>
      <output type='gz.msgs.Twist' topic='/cmd_vel'>linear: {x: -0.5}, angular: {z: 0.0}</output>
    </plugin>
    <gravity>0 0 -9.8000000000000007</gravity>
    <magnetic_field>5.5644999999999998e-06 2.2875799999999999e-05 -4.2388400000000002e-05</magnetic_field>
    <atmosphere type='adiabatic'/>
    <scene>
      <ambient>0.400000006 0.400000006 0.400000006 1</ambient>
      <background>0.699999988 0.699999988 0.699999988 1</background>
      <shadows>true</shadows>
    </scene>
    <model name='ground_plane'>
      <static>true</static>
      <link name='link'>
        <collision name='collision'>
          <geometry>
            <plane>
              <normal>0 0 1</normal>
              <size>1 1</size>
            </plane>
          </geometry>
          <surface>
            <friction>
              <ode/>
            </friction>
            <bounce/>
            <contact/>
          </surface>
        </collision>
        <visual name='visual'>
          <geometry>
            <plane>
              <normal>0 0 1</normal>
              <size>100 100</size>
            </plane>
          </geometry>
          <material>
            <ambient>0.800000012 0.800000012 0.800000012 1</ambient>
            <diffuse>0.800000012 0.800000012 0.800000012 1</diffuse>
            <specular>0.800000012 0.800000012 0.800000012 1</specular>
          </material>
        </visual>
        <pose>0 0 0 0 0 0</pose>
        <inertial>
          <pose>0 0 0 0 0 0</pose>
          <mass>1</mass>
          <inertia>
            <ixx>1</ixx>
            <ixy>0</ixy>
            <ixz>0</ixz>
            <iyy>1</iyy>
            <iyz>0</iyz>
            <izz>1</izz>
          </inertia>
        </inertial>
        <enable_wind>false</enable_wind>
      </link>
      <pose>0 0 0 0 0 0</pose>
      <self_collide>false</self_collide>
    </model>
    <model name='wall'>
      <static>true</static>
      <pose>5 0 0 0 0 0</pose>
      <link name='box'>
        <visual name='visual'>
          <geometry>
            <box>
              <size>0.5 10 2</size>
            </box>
          </geometry>
          <material>
            <ambient>0 0 1 1</ambient>
            <diffuse>0 0 1 1</diffuse>
            <specular>0 0 1 1</specular>
          </material>
        </visual>
        <collision name='collision'>
          <geometry>
            <box>
              <size>0.5 10 2</size>
            </box>
          </geometry>
          <surface>
            <friction>
              <ode/>
            </friction>
            <bounce/>
            <contact/>
          </surface>
        </collision>
        <pose>0 0 0 0 0 0</pose>
        <inertial>
          <pose>0 0 0 0 0 0</pose>
          <mass>1</mass>
          <inertia>
            <ixx>1</ixx>
            <ixy>0</ixy>
            <ixz>0</ixz>
            <iyy>1</iyy>
            <iyz>0</iyz>
            <izz>1</izz>
          </inertia>
        </inertial>
        <enable_wind>false</enable_wind>
      </link>
      <self_collide>false</self_collide>
    </model>
    <model name='wall5'>
      <static>true</static>
      <pose>-8.2442197799682617 4.3869099617004395 0 0 0 0</pose>
      <link name='box'>
        <visual name='visual'>
          <geometry>
            <box>
              <size>0.5 10 2</size>
            </box>
          </geometry>
          <material>
            <ambient>0 0 1 1</ambient>
            <diffuse>0 0 1 1</diffuse>
            <specular>0 0 1 1</specular>
          </material>
        </visual>
        <collision name='collision'>
          <geometry>
            <box>
              <size>0.5 10 2</size>
            </box>
          </geometry>
          <surface>
            <friction>
              <ode/>
            </friction>
            <bounce/>
            <contact/>
          </surface>
        </collision>
        <pose>0 0 0 0 0 0</pose>
        <inertial>
          <pose>0 0 0 0 0 0</pose>
          <mass>1</mass>
          <inertia>
            <ixx>1</ixx>
            <ixy>0</ixy>
            <ixz>0</ixz>
            <iyy>1</iyy>
            <iyz>0</iyz>
            <izz>1</izz>
          </inertia>
        </inertial>
        <enable_wind>false</enable_wind>
      </link>
      <self_collide>false</self_collide>
    </model>
    <model name='wall4'>
      <static>true</static>
      <pose>-7.0035514831542969 1.5503436326980591 -0.36632499098777771 0 0 1.5731600067873759</pose>
      <link name='box'>
        <visual name='visual'>
          <geometry>
            <box>
              <size>0.5 10 2</size>
            </box>
          </geometry>
          <material>
            <ambient>0 0 1 1</ambient>
            <diffuse>0 0 1 1</diffuse>
            <specular>0 0 1 1</specular>
          </material>
        </visual>
        <collision name='collision'>
          <geometry>
            <box>
              <size>0.5 10 2</size>
            </box>
          </geometry>
          <surface>
            <friction>
              <ode/>
            </friction>
            <bounce/>
            <contact/>
          </surface>
        </collision>
        <pose>0 0 0 0 0 0</pose>
        <inertial>
          <pose>0 0 0 0 0 0</pose>
          <mass>1</mass>
          <inertia>
            <ixx>1</ixx>
            <ixy>0</ixy>
            <ixz>0</ixz>
            <iyy>1</iyy>
            <iyz>0</iyz>
            <izz>1</izz>
          </inertia>
        </inertial>
        <enable_wind>false</enable_wind>
      </link>
      <self_collide>false</self_collide>
    </model>
    <model name='wall2'>
      <static>true</static>
      <pose>0 -6 0 0 0 -1.5500000000000003</pose>
      <link name='box'>
        <visual name='visual'>
          <geometry>
            <box>
              <size>0.5 10 2</size>
            </box>
          </geometry>
          <material>
            <ambient>0 0 1 1</ambient>
            <diffuse>0 0 1 1</diffuse>
            <specular>0 0 1 1</specular>
          </material>
        </visual>
        <collision name='collision'>
          <geometry>
            <box>
              <size>0.5 10 2</size>
            </box>
          </geometry>
          <surface>
            <friction>
              <ode/>
            </friction>
            <bounce/>
            <contact/>
          </surface>
        </collision>
        <pose>0 0 0 0 0 0</pose>
        <inertial>
          <pose>0 0 0 0 0 0</pose>
          <mass>1</mass>
          <inertia>
            <ixx>1</ixx>
            <ixy>0</ixy>
            <ixz>0</ixz>
            <iyy>1</iyy>
            <iyz>0</iyz>
            <izz>1</izz>
          </inertia>
        </inertial>
        <enable_wind>false</enable_wind>
      </link>
      <self_collide>false</self_collide>
    </model>
    <model name='wall3'>
      <static>true</static>
      <pose>0 6 0 0 0 -1.5500000000000003</pose>
      <link name='box'>
        <visual name='visual'>
          <geometry>
            <box>
              <size>0.5 10 2</size>
            </box>
          </geometry>
          <material>
            <ambient>0 0 1 1</ambient>
            <diffuse>0 0 1 1</diffuse>
            <specular>0 0 1 1</specular>
          </material>
        </visual>
        <collision name='collision'>
          <geometry>
            <box>
              <size>0.5 10 2</size>
            </box>
          </geometry>
          <surface>
            <friction>
              <ode/>
            </friction>
            <bounce/>
            <contact/>
          </surface>
        </collision>
        <pose>0 0 0 0 0 0</pose>
        <inertial>
          <pose>0 0 0 0 0 0</pose>
          <mass>1</mass>
          <inertia>
            <ixx>1</ixx>
            <ixy>0</ixy>
            <ixz>0</ixz>
            <iyy>1</iyy>
            <iyz>0</iyz>
            <izz>1</izz>
          </inertia>
        </inertial>
        <enable_wind>false</enable_wind>
      </link>
      <self_collide>false</self_collide>
    </model>
    <model name='vehicle_blue' canonical_link='chassis'>
      <frame name='lidar_frame' attached_to='chassis'>
        <pose>0.80000000000000004 0 0.5 0 0 0</pose>
      </frame>
      <pose>2.0000000000000004 -1.1102230246251565e-16 0 0 0 -1.5600000000000009</pose>
      <link name='chassis'>
        <sensor name='imu_sensor' type='imu'>
          <pose>0 0 0 0 0 0</pose>
          <topic>imu</topic>
          <update_rate>1</update_rate>
          <enable_metrics>false</enable_metrics>
          <imu>
            <orientation_reference_frame>
              <localization>CUSTOM</localization>
              <custom_rpy>0 0 0</custom_rpy>
              <grav_dir_x>1 0 0</grav_dir_x>
            </orientation_reference_frame>
            <angular_velocity>
              <x>
                <noise type='none'>
                  <mean>0</mean>
                  <stddev>0</stddev>
                  <bias_mean>0</bias_mean>
                  <bias_stddev>0</bias_stddev>
                  <dynamic_bias_stddev>0</dynamic_bias_stddev>
                  <dynamic_bias_correlation_time>0</dynamic_bias_correlation_time>
                  <precision>0</precision>
                </noise>
              </x>
              <y>
                <noise type='none'>
                  <mean>0</mean>
                  <stddev>0</stddev>
                  <bias_mean>0</bias_mean>
                  <bias_stddev>0</bias_stddev>
                  <dynamic_bias_stddev>0</dynamic_bias_stddev>
                  <dynamic_bias_correlation_time>0</dynamic_bias_correlation_time>
                  <precision>0</precision>
                </noise>
              </y>
              <z>
                <noise type='none'>
                  <mean>0</mean>
                  <stddev>0</stddev>
                  <bias_mean>0</bias_mean>
                  <bias_stddev>0</bias_stddev>
                  <dynamic_bias_stddev>0</dynamic_bias_stddev>
                  <dynamic_bias_correlation_time>0</dynamic_bias_correlation_time>
                  <precision>0</precision>
                </noise>
              </z>
            </angular_velocity>
            <linear_acceleration>
              <x>
                <noise type='none'>
                  <mean>0</mean>
                  <stddev>0</stddev>
                  <bias_mean>0</bias_mean>
                  <bias_stddev>0</bias_stddev>
                  <dynamic_bias_stddev>0</dynamic_bias_stddev>
                  <dynamic_bias_correlation_time>0</dynamic_bias_correlation_time>
                  <precision>0</precision>
                </noise>
              </x>
              <y>
                <noise type='none'>
                  <mean>0</mean>
                  <stddev>0</stddev>
                  <bias_mean>0</bias_mean>
                  <bias_stddev>0</bias_stddev>
                  <dynamic_bias_stddev>0</dynamic_bias_stddev>
                  <dynamic_bias_correlation_time>0</dynamic_bias_correlation_time>
                  <precision>0</precision>
                </noise>
              </y>
              <z>
                <noise type='none'>
                  <mean>0</mean>
                  <stddev>0</stddev>
                  <bias_mean>0</bias_mean>
                  <bias_stddev>0</bias_stddev>
                  <dynamic_bias_stddev>0</dynamic_bias_stddev>
                  <dynamic_bias_correlation_time>0</dynamic_bias_correlation_time>
                  <precision>0</precision>
                </noise>
              </z>
            </linear_acceleration>
            <enable_orientation>true</enable_orientation>
          </imu>
        </sensor>
        <sensor name='gpu_lidar' type='gpu_lidar'>
          <pose>0.80000000000000004 0 0.5 0 0 0</pose>
          <topic>lidar</topic>
          <update_rate>10</update_rate>
          <enable_metrics>false</enable_metrics>
          <lidar>
            <scan>
              <horizontal>
                <samples>640</samples>
                <resolution>1</resolution>
                <min_angle>-1.396263</min_angle>
                <max_angle>1.396263</max_angle>
              </horizontal>
              <vertical>
                <samples>1</samples>
                <min_angle>0</min_angle>
                <max_angle>0</max_angle>
                <resolution>0.01</resolution>
              </vertical>
            </scan>
            <range>
              <min>0.080000000000000002</min>
              <max>10</max>
              <resolution>0.01</resolution>
            </range>
            <noise>
              <type>none</type>
              <mean>0</mean>
              <stddev>0</stddev>
            </noise>
            <visibility_mask>4294967295</visibility_mask>
          </lidar>
        </sensor>
        <pose>0.5 0 0.40000000000000002 0 0 0</pose>
        <inertial>
          <mass>1.14395</mass>
          <inertia>
            <ixx>0.126164</ixx>
            <ixy>0</ixy>
            <ixz>0</ixz>
            <iyy>0.41651899999999997</iyy>
            <iyz>0</iyz>
            <izz>0.481014</izz>
          </inertia>
          <pose>0 0 0 0 0 0</pose>
        </inertial>
        <visual name='visual'>
          <geometry>
            <box>
              <size>2 1 0.5</size>
            </box>
          </geometry>
          <material>
            <ambient>0 0 1 1</ambient>
            <diffuse>0 0 1 1</diffuse>
            <specular>0 0 1 1</specular>
          </material>
        </visual>
        <collision name='collision'>
          <geometry>
            <box>
              <size>2 1 0.5</size>
            </box>
          </geometry>
          <surface>
            <friction>
              <ode/>
            </friction>
            <bounce/>
            <contact/>
          </surface>
        </collision>
        <enable_wind>false</enable_wind>
      </link>
      <link name='left_wheel'>
        <pose>-4.4408920985006262e-16 0.59999999999999964 0.40000000000000002 -1.5707000000000002 7.8505379053005567e-16 -1.5697143519272498e-16</pose>
        <inertial>
          <mass>2</mass>
          <inertia>
            <ixx>0.14583299999999999</ixx>
            <ixy>0</ixy>
            <ixz>0</ixz>
            <iyy>0.14583299999999999</iyy>
            <iyz>0</iyz>
            <izz>0.125</izz>
          </inertia>
          <pose>0 0 0 0 0 0</pose>
        </inertial>
        <visual name='visual'>
          <geometry>
            <cylinder>
              <radius>0.40000000000000002</radius>
              <length>0.20000000000000001</length>
            </cylinder>
          </geometry>
          <material>
            <ambient>1 0 0 1</ambient>
            <diffuse>1 0 0 1</diffuse>
            <specular>1 0 0 1</specular>
          </material>
        </visual>
        <collision name='collision'>
          <geometry>
            <cylinder>
              <radius>0.40000000000000002</radius>
              <length>0.20000000000000001</length>
            </cylinder>
          </geometry>
          <surface>
            <friction>
              <ode/>
            </friction>
            <bounce/>
            <contact/>
          </surface>
        </collision>
        <enable_wind>false</enable_wind>
      </link>
      <link name='right_wheel'>
        <pose>3.3306690738754696e-16 -0.60000000000000053 0.40000000000000002 -1.5707000000000002 7.8505379053005567e-16 -1.5697143519272498e-16</pose>
        <inertial>
          <mass>1</mass>
          <inertia>
            <ixx>0.14583299999999999</ixx>
            <ixy>0</ixy>
            <ixz>0</ixz>
            <iyy>0.14583299999999999</iyy>
            <iyz>0</iyz>
            <izz>0.125</izz>
          </inertia>
          <pose>0 0 0 0 0 0</pose>
        </inertial>
        <visual name='visual'>
          <geometry>
            <cylinder>
              <radius>0.40000000000000002</radius>
              <length>0.20000000000000001</length>
            </cylinder>
          </geometry>
          <material>
            <ambient>1 0 0 1</ambient>
            <diffuse>1 0 0 1</diffuse>
            <specular>1 0 0 1</specular>
          </material>
        </visual>
        <collision name='collision'>
          <geometry>
            <cylinder>
              <radius>0.40000000000000002</radius>
              <length>0.20000000000000001</length>
            </cylinder>
          </geometry>
          <surface>
            <friction>
              <ode/>
            </friction>
            <bounce/>
            <contact/>
          </surface>
        </collision>
        <enable_wind>false</enable_wind>
      </link>
      <frame name='caster_frame' attached_to='chassis'>
        <pose>0.80000000000000004 0 -0.20000000000000001 0 0 0</pose>
      </frame>
      <link name='caster'>
        <pose>1.3000000000000005 4.4408920985006262e-16 0.20000000000000001 0 0 0</pose>
        <inertial>
          <mass>1</mass>
          <inertia>
            <ixx>0.10000000000000001</ixx>
            <ixy>0</ixy>
            <ixz>0</ixz>
            <iyy>0.10000000000000001</iyy>
            <iyz>0</iyz>
            <izz>0.10000000000000001</izz>
          </inertia>
          <pose>0 0 0 0 0 0</pose>
        </inertial>
        <visual name='visual'>
          <geometry>
            <sphere>
              <radius>0.20000000000000001</radius>
            </sphere>
          </geometry>
          <material>
            <ambient>0 1 0 1</ambient>
            <diffuse>0 1 0 1</diffuse>
            <specular>0 1 0 1</specular>
          </material>
        </visual>
        <collision name='collision'>
          <geometry>
            <sphere>
              <radius>0.20000000000000001</radius>
            </sphere>
          </geometry>
          <surface>
            <friction>
              <ode/>
            </friction>
            <bounce/>
            <contact/>
          </surface>
        </collision>
        <enable_wind>false</enable_wind>
      </link>
      <joint name='left_wheel_joint' type='revolute'>
        <pose>1.9721522630525295e-31 -4.9960036108132044e-16 -1.1102230246251565e-16 -1.2154326714572542e-63 9.8607613152626476e-32 -2.4651903288156619e-32</pose>
        <parent>chassis</parent>
        <child>left_wheel</child>
        <axis>
          <xyz>9.8609987333971959e-32 9.6326794747692026e-05 0.99999999536057438</xyz>
          <limit>
            <lower>-1.7976900000000001e+308</lower>
            <upper>1.7976900000000001e+308</upper>
            <effort>inf</effort>
            <velocity>inf</velocity>
            <stiffness>100000000</stiffness>
            <dissipation>1</dissipation>
          </limit>
          <dynamics>
            <spring_reference>0</spring_reference>
            <spring_stiffness>0</spring_stiffness>
            <damping>0</damping>
            <friction>0</friction>
          </dynamics>
        </axis>
      </joint>
      <joint name='right_wheel_joint' type='revolute'>
        <pose>-4.9303806576313238e-32 2.7755575615628914e-16 -2.2204460492503131e-16 -1.2154326714572542e-63 9.8607613152626476e-32 -2.4651903288156619e-32</pose>
        <parent>chassis</parent>
        <child>right_wheel</child>
        <axis>
          <xyz>9.8609987333971959e-32 9.6326794747692026e-05 0.99999999536057438</xyz>
          <limit>
            <lower>-1.7976900000000001e+308</lower>
            <upper>1.7976900000000001e+308</upper>
            <effort>inf</effort>
            <velocity>inf</velocity>
            <stiffness>100000000</stiffness>
            <dissipation>1</dissipation>
          </limit>
          <dynamics>
            <spring_reference>0</spring_reference>
            <spring_stiffness>0</spring_stiffness>
            <damping>0</damping>
            <friction>0</friction>
          </dynamics>
        </axis>
      </joint>
      <joint name='caster_wheel' type='ball'>
        <parent>chassis</parent>
        <child>caster</child>
        <pose>0 0 0 0 0 0</pose>
      </joint>
      <plugin name='gz::sim::systems::DiffDrive' filename='gz-sim-diff-drive-system'>
        <left_joint>left_wheel_joint</left_joint>
        <right_joint>right_wheel_joint</right_joint>
        <wheel_separation>1.2</wheel_separation>
        <wheel_radius>0.4</wheel_radius>
        <odom_publish_frequency>1</odom_publish_frequency>
        <topic>cmd_vel</topic>
      </plugin>
      <static>false</static>
      <self_collide>false</self_collide>
    </model>
    <include>
      <uri>https://fuel.gazebosim.org/1.0/OpenRobotics/models/Coke</uri>
      <name>Coke1</name>
      <pose>10 0.10000000000000001 0 0 0 0</pose>
    </include>
    <light name='sun' type='directional'>
      <pose>0 0 10 0 0 0</pose>
      <cast_shadows>true</cast_shadows>
      <intensity>1</intensity>
      <direction>-0.5 0.10000000000000001 -0.90000000000000002</direction>
      <diffuse>0.800000012 0.800000012 0.800000012 1</diffuse>
      <specular>0.200000003 0.200000003 0.200000003 1</specular>
      <attenuation>
        <range>1000</range>
        <linear>0.01</linear>
        <constant>0.90000000000000002</constant>
        <quadratic>0.001</quadratic>
      </attenuation>
      <spot>
        <inner_angle>0</inner_angle>
        <outer_angle>0</outer_angle>
        <falloff>0</falloff>
      </spot>
    </light>
  </world>
</sdf>
